<?xml version="1.0" encoding="utf-8"?>
<robot name="ur10e_robot">
	<link name="base_link">
		<visual>
			<origin rpy="0 0 3.141592653589793" xyz="0 0 0" />
			<geometry>
				<mesh filename="meshes/base.dae" />
			</geometry>
			<material name="LightGrey">
				<color rgba="0.7 0.7 0.7 1.0" />
			</material>
		</visual>
	</link>
	<link name="shoulder_link">
		<visual>
			<origin rpy="0 0 3.141592653589793" xyz="0 0 0" />
			<geometry>
				<mesh filename="meshes/shoulder.dae" />
			</geometry>
			<material name="LightGrey">
				<color rgba="0.7 0.7 0.7 1.0" />
			</material>
		</visual>
	</link>
	<link name="upper_arm_link">
		<visual>
			<origin rpy="1.5707963267948966 0 -1.5707963267948966" xyz="0 0 0.1762" />
			<geometry>
				<mesh filename="meshes/upperarm.dae" />
			</geometry>
			<material name="LightGrey">
				<color rgba="0.7 0.7 0.7 1.0" />
			</material>
		</visual>
	</link>
	<link name="forearm_link">
		<visual>
			<origin rpy="1.5707963267948966 0 -1.5707963267948966" xyz="0 0 0.0393" />
			<geometry>
				<mesh filename="meshes/forearm.dae" />
			</geometry>
			<material name="LightGrey">
				<color rgba="0.7 0.7 0.7 1.0" />
			</material>
		</visual>
	</link>
	<link name="wrist_1_link">
		<visual>
			<origin rpy="1.5707963267948966 0 0" xyz="0 0 -0.135" />
			<geometry>
				<mesh filename="meshes/wrist1.dae" />
			</geometry>
			<material name="LightGrey">
				<color rgba="0.7 0.7 0.7 1.0" />
			</material>
		</visual>
	</link>
	<link name="wrist_2_link">
		<visual>
			<origin rpy="0 0 0" xyz="0 0 -0.12" />
			<geometry>
				<mesh filename="meshes/wrist2.dae" />
			</geometry>
			<material name="LightGrey">
				<color rgba="0.7 0.7 0.7 1.0" />
			</material>
		</visual>
	</link>
	<link name="wrist_3_link">
		<visual>
			<origin rpy="1.5707963267948966 0 0" xyz="0 0 -0.1168" />
			<geometry>
				<mesh filename="meshes/wrist3.dae" />
			</geometry>
			<material name="LightGrey">
				<color rgba="0.7 0.7 0.7 1.0" />
			</material>
		</visual>
	</link>
	<joint name="shoulder_pan_joint" type="revolute">
		<parent link="base_link" />
		<child link="shoulder_link" />
		<origin rpy="0 0 0" xyz="0 0 0.1807" />
		<axis xyz="0 0 1" />
		<limit effort="330.0" lower="-6.283185307179586" upper="6.283185307179586"
			velocity="2.0943951023931953" />
		<dynamics damping="0" friction="0" />
	</joint>
	<joint name="shoulder_lift_joint" type="revolute">
		<parent link="shoulder_link" />
		<child link="upper_arm_link" />
		<origin rpy="1.570796327 0 0" xyz="0 0 0" />
		<axis xyz="0 0 1" />
		<limit effort="330.0" lower="-6.283185307179586" upper="6.283185307179586"
			velocity="2.0943951023931953" />
		<dynamics damping="0" friction="0" />
	</joint>
	<joint name="elbow_joint" type="revolute">
		<parent link="upper_arm_link" />
		<child link="forearm_link" />
		<origin rpy="0 0 0" xyz="-0.6127 0 0" />
		<axis xyz="0 0 1" />
		<limit effort="150.0" lower="-3.141592653589793" upper="3.141592653589793"
			velocity="3.141592653589793" />
		<dynamics damping="0" friction="0" />
	</joint>
	<joint name="wrist_1_joint" type="revolute">
		<parent link="forearm_link" />
		<child link="wrist_1_link" />
		<origin rpy="0 0 0" xyz="-0.57155 0 0.17415" />
		<axis xyz="0 0 1" />
		<limit effort="56.0" lower="-6.283185307179586" upper="6.283185307179586"
			velocity="3.141592653589793" />
		<dynamics damping="0" friction="0" />
	</joint>
	<joint name="wrist_2_joint" type="revolute">
		<parent link="wrist_1_link" />
		<child link="wrist_2_link" />
		<origin rpy="1.570796327 0 0" xyz="0 -0.11985 -2.458164590756244e-11" />
		<axis xyz="0 0 1" />
		<limit effort="56.0" lower="-6.283185307179586" upper="6.283185307179586"
			velocity="3.141592653589793" />
		<dynamics damping="0" friction="0" />
	</joint>
	<joint name="wrist_3_joint" type="revolute">
		<parent link="wrist_2_link" />
		<child link="wrist_3_link" />
		<origin rpy="1.570796326589793 3.141592653589793 3.141592653589793"
			xyz="0 0.11655 -2.390480459346185e-11" />
		<axis xyz="0 0 1" />
		<limit effort="56.0" lower="-6.283185307179586" upper="6.283185307179586"
			velocity="3.141592653589793" />
		<dynamics damping="0" friction="0" />
	</joint>
</robot>