<?xml version="1.0" encoding="utf-8"?>
<robot name="robotiq_2f85_v3">
	<link name="robotiq_85_base_link">
		<visual>
			<origin xyz="0 0 0" rpy="0 0 0" />
			<geometry>
				<mesh filename="meshes/robotiq_85_base_link_fine.STL" />
			</geometry>
			<material name="">
				<color rgba="0.1 0.1 0.1 1" />
			</material>
		</visual>
	</link>
	<link name="left_outer_knuckle">
		<visual>
			<origin xyz="0 0 0" rpy="0 0 0" />
			<geometry>
				<mesh filename="meshes/outer_knuckle_fine.STL" />
			</geometry>
			<material name="">
				<color rgba="0.1 0.1 0.1 1" />
			</material>
		</visual>
	</link>
	<link name="left_outer_finger">
		<visual>
			<origin xyz="0 0 0" rpy="0 0 0" />
			<geometry>
				<mesh filename="meshes/outer_finger_fine.STL" />
			</geometry>
			<material name="">
				<color rgba="0.1 0.1 0.1 1" />
			</material>
		</visual>
	</link>
	<link name="left_inner_knuckle">
		<visual>
			<origin xyz="0 0 0" rpy="0 0 0" />
			<geometry>
				<mesh filename="meshes/inner_knuckle_fine.STL" />
			</geometry>
			<material name="">
				<color rgba="0.1 0.1 0.1 1" />
			</material>
		</visual>
	</link>
	<link name="left_inner_finger">
		<visual>
			<origin xyz="0 0 0" rpy="0 0 0" />
			<geometry>
				<mesh filename="meshes/inner_finger_fine.STL" />
			</geometry>
			<material name="">
				<color rgba="0.1 0.1 0.1 1" />
			</material>
		</visual>
	</link>
	<link name="right_inner_knuckle">
		<visual>
			<origin xyz="0 0 0" rpy="0 0 0" />
			<geometry>
				<mesh filename="meshes/inner_knuckle_fine.STL" />
			</geometry>
			<material name="">
				<color rgba="0.1 0.1 0.1 1" />
			</material>
		</visual>
	</link>
	<link name="right_inner_finger">
		<visual>
			<origin xyz="0 0 0" rpy="0 0 0" />
			<geometry>
				<mesh filename="meshes/inner_finger_fine.STL" />
			</geometry>
			<material name="">
				<color rgba="0.1 0.1 0.1 1" />
			</material>
		</visual>
	</link>
	<link name="right_outer_knuckle">
		<visual>
			<origin xyz="0 0 0" rpy="0 0 0" />
			<geometry>
				<mesh filename="meshes/outer_knuckle_fine.STL" />
			</geometry>
			<material name="">
				<color rgba="0.1 0.1 0.1 1" />
			</material>
		</visual>
	</link>
	<link name="right_outer_finger">
		<visual>
			<origin xyz="0 0 0" rpy="0 0 0" />
			<geometry>
				<mesh filename="meshes/outer_finger_fine.STL" />
			</geometry>
			<material name="">
				<color rgba="0.1 0.1 0.1 1" />
			</material>
		</visual>
	</link>
	<joint name="finger_joint" type="revolute">
		<origin xyz="0.0306011444260539 0 0.0627920162695395" rpy="0 0 0" />
		<parent link="robotiq_85_base_link" />
		<child link="left_outer_knuckle" />
		<axis xyz="0 -1 0" />
		<limit lower="0" upper="0.725" velocity="2.0" effort="1000" />
	</joint>
	<joint name="left_outer_finger_joint" type="fixed">
		<origin xyz="0.0316910442266543 0 -0.00193396375724605" rpy="0 0 0" />
		<parent link="left_outer_knuckle" />
		<child link="left_outer_finger" />
		<axis xyz="0 -1 0" />
	</joint>
	<joint name="left_inner_knuckle_joint" type="revolute">
		<origin xyz="0.0127000000001501 0 0.0693074999999639" rpy="0 0 0" />
		<parent link="robotiq_85_base_link" />
		<child link="left_inner_knuckle" />
		<axis xyz="0 -1 0" />
		<limit lower="0" upper="0.8757" velocity="2.0" effort="1000" />
		<mimic joint="finger_joint" multiplier="1" offset="0" />
	</joint>
	<joint name="left_inner_finger_joint" type="revolute">
		<origin xyz="0.034585310861294 0 0.0454970193817975" rpy="0 0 0" />
		<parent link="left_inner_knuckle" />
		<child link="left_inner_finger" />
		<axis xyz="0 -1 0" />
		<limit lower="0" upper="0.8757" velocity="2.0" effort="1000" />
		<mimic joint="finger_joint" multiplier="-1" offset="0" />
	</joint>
	<joint name="right_inner_knuckle_joint" type="revolute">
		<origin xyz="-0.0126999999998499 0 0.0693075000000361" rpy="0 0 3.14159265358979" />
		<parent link="robotiq_85_base_link" />
		<child link="right_inner_knuckle" />
		<axis xyz="0 1 0" />
		<limit lower="0" upper="0.8757" velocity="2.0" effort="1000" />
		<mimic joint="finger_joint" multiplier="-1" offset="0" />
	</joint>
	<joint name="right_inner_finger_joint" type="revolute">
		<origin xyz="0.0341060475457406 0 0.0458573878541688" rpy="0 0 0" />
		<parent link="right_inner_knuckle" />
		<child link="right_inner_finger" />
		<axis xyz="0 1 0" />
		<limit lower="0" upper="0.8757" velocity="2.0" effort="1000" />
		<mimic joint="finger_joint" multiplier="1" offset="0" />
	</joint>
	<joint name="right_outer_knuckle_joint" type="revolute">
		<origin xyz="-0.0306011444258893 0 0.0627920162695395" rpy="0 0 3.14159265358979" />
		<parent link="robotiq_85_base_link" />
		<child link="right_outer_knuckle" />
		<axis xyz="0 1 0" />
		<limit lower="0" upper="0.8757" velocity="2.0" effort="1000" />
		<mimic joint="finger_joint" multiplier="-1" offset="0" />
	</joint>
	<joint name="right_outer_finger_joint" type="fixed">
		<origin xyz="0.0317095909367246 0 -0.0016013564954687" rpy="0 0 0" />
		<parent link="right_outer_knuckle" />
		<child link="right_outer_finger" />
		<axis xyz="0 1 0" />
	</joint>
</robot>