<?xml version="1.0" encoding="utf-8"?>
<robot name="robotiq_2f85_v3">
	<link name="robotiq_arg2f_base_link">
		<visual>
			<origin rpy="0 0 0" xyz="0 0 0" />
			<geometry>
				<mesh filename="meshes/robotiq_arg2f_85_base_link.dae"
					scale="0.001 0.001 0.001" />
			</geometry>
			<material name="">
				<color rgba="0.1 0.1 0.1 1" />
			</material>
		</visual>
	</link>
	<link name="left_outer_knuckle">
		<visual>
			<origin rpy="0 0 0" xyz="0 0 0" />
			<geometry>
				<mesh filename="meshes/robotiq_arg2f_85_outer_knuckle.dae"
					scale="0.001 0.001 0.001" />
			</geometry>
			<material name="">
				<color rgba="0.792156862745098 0.819607843137255 0.933333333333333 1" />
			</material>
		</visual>
	</link>
	<link name="left_outer_finger">
		<visual>
			<origin rpy="0 0 0" xyz="0 0 0" />
			<geometry>
				<mesh filename="meshes/robotiq_arg2f_85_outer_finger.dae"
					scale="0.001 0.001 0.001" />
			</geometry>
			<material name="">
				<color rgba="0.1 0.1 0.1 1" />
			</material>
		</visual>
	</link>
	<link name="left_inner_finger">
		<visual>
			<origin rpy="0 0 0" xyz="0 0 0" />
			<geometry>
				<mesh filename="meshes/robotiq_arg2f_85_inner_finger.dae"
					scale="0.001 0.001 0.001" />
			</geometry>
			<material name="">
				<color rgba="0.1 0.1 0.1 1" />
			</material>
		</visual>
	</link>
	<link name="left_inner_finger_pad">
		<visual>
			<origin rpy="0 0 0" xyz="0 0 0" />
			<geometry>
				<box size="0.022 0.00635 0.0375" />
			</geometry>
			<material name="">
				<color rgba="0.9 0.9 0.9 1" />
			</material>
		</visual>
	</link>
	<link name="left_inner_knuckle">
		<visual>
			<origin rpy="0 0 0" xyz="0 0 0" />
			<geometry>
				<mesh filename="meshes/robotiq_arg2f_85_inner_knuckle.dae"
					scale="0.001 0.001 0.001" />
			</geometry>
			<material name="">
				<color rgba="0.1 0.1 0.1 1" />
			</material>
		</visual>
	</link>
	<link name="right_outer_knuckle">
		<visual>
			<origin rpy="0 0 0" xyz="0 0 0" />
			<geometry>
				<mesh filename="meshes/robotiq_arg2f_85_outer_knuckle.dae"
					scale="0.001 0.001 0.001" />
			</geometry>
			<material name="">
				<color rgba="0.792156862745098 0.819607843137255 0.933333333333333 1" />
			</material>
		</visual>
	</link>
	<link name="right_outer_finger">
		<visual>
			<origin rpy="0 0 0" xyz="0 0 0" />
			<geometry>
				<mesh filename="meshes/robotiq_arg2f_85_outer_finger.dae"
					scale="0.001 0.001 0.001" />
			</geometry>
			<material name="">
				<color rgba="0.1 0.1 0.1 1" />
			</material>
		</visual>
	</link>
	<link name="right_inner_finger">
		<visual>
			<origin rpy="0 0 0" xyz="0 0 0" />
			<geometry>
				<mesh filename="meshes/robotiq_arg2f_85_inner_finger.dae"
					scale="0.001 0.001 0.001" />
			</geometry>
			<material name="">
				<color rgba="0.1 0.1 0.1 1" />
			</material>
		</visual>
	</link>
	<link name="right_inner_finger_pad">
		<visual>
			<origin rpy="0 0 0" xyz="0 0 0" />
			<geometry>
				<box size="0.022 0.00635 0.0375" />
			</geometry>
			<material name="">
				<color rgba="0.9 0.9 0.9 1" />
			</material>
		</visual>
	</link>
	<link name="right_inner_knuckle">
		<visual>
			<origin rpy="0 0 0" xyz="0 0 0" />
			<geometry>
				<mesh filename="meshes/robotiq_arg2f_85_inner_knuckle.dae"
					scale="0.001 0.001 0.001" />
			</geometry>
			<material name="">
				<color rgba="0.1 0.1 0.1 1" />
			</material>
		</visual>
	</link>
	<joint name="finger_joint" type="revolute">
		<origin rpy="0 0 3.141592653589793" xyz="0 -0.0306011 0.054904" />
		<parent link="robotiq_arg2f_base_link" />
		<child link="left_outer_knuckle" />
		<axis xyz="1 0 0" />
		<limit effort="1000" lower="0" upper="0.8" velocity="2.0" />
	</joint>
	<joint name="left_outer_finger_joint" type="fixed">
		<origin rpy="0 0 0" xyz="0 0.0315 -0.0041" />
		<parent link="left_outer_knuckle" />
		<child link="left_outer_finger" />
		<axis xyz="1 0 0" />
	</joint>
	<joint name="left_inner_knuckle_joint" type="revolute">
		<origin rpy="0 0 3.141592653589793" xyz="0 -0.0127 0.06142" />
		<parent link="robotiq_arg2f_base_link" />
		<child link="left_inner_knuckle" />
		<axis xyz="1 0 0" />
		<limit effort="1000" lower="0" upper="0.8757" velocity="2.0" />
		<mimic joint="finger_joint" multiplier="1" offset="0" />
	</joint>
	<joint name="left_inner_finger_joint" type="revolute">
		<origin rpy="0 0 0" xyz="0 0.0061 0.0471" />
		<parent link="left_outer_finger" />
		<child link="left_inner_finger" />
		<axis xyz="1 0 0" />
		<limit effort="1000" lower="-0.8757" upper="0" velocity="2.0" />
		<mimic joint="finger_joint" multiplier="-1" offset="0" />
	</joint>
	<joint name="left_inner_finger_pad_joint" type="fixed">
		<origin rpy="0 0 0" xyz="0 -0.0220203446692936 0.03242" />
		<parent link="left_inner_finger" />
		<child link="left_inner_finger_pad" />
		<axis xyz="0 0 1" />
	</joint>
	<joint name="right_outer_knuckle_joint" type="revolute">
		<origin rpy="0 0 0" xyz="0 0.0306011 0.054904" />
		<parent link="robotiq_arg2f_base_link" />
		<child link="right_outer_knuckle" />
		<axis xyz="1 0 0" />
		<limit effort="1000" lower="0" upper="0.81" velocity="2.0" />
		<mimic joint="finger_joint" multiplier="1" offset="0" />
	</joint>
	<joint name="right_outer_finger_joint" type="fixed">
		<origin rpy="0 0 0" xyz="0 0.0315 -0.0041" />
		<parent link="right_outer_knuckle" />
		<child link="right_outer_finger" />
		<axis xyz="1 0 0" />
	</joint>
	<joint name="right_inner_knuckle_joint" type="revolute">
		<origin rpy="0 0 0.0" xyz="0 0.0127 0.06142" />
		<parent link="robotiq_arg2f_base_link" />
		<child link="right_inner_knuckle" />
		<axis xyz="1 0 0" />
		<limit effort="1000" lower="0" upper="0.8757" velocity="2.0" />
		<mimic joint="finger_joint" multiplier="1" offset="0" />
	</joint>
	<joint name="right_inner_finger_joint" type="revolute">
		<origin rpy="0 0 0" xyz="0 0.0061 0.0471" />
		<parent link="right_outer_finger" />
		<child link="right_inner_finger" />
		<axis xyz="1 0 0" />
		<limit effort="1000" lower="-0.8757" upper="0" velocity="2.0" />
		<mimic joint="finger_joint" multiplier="-1" offset="0" />
	</joint>
	<joint name="right_inner_finger_pad_joint" type="fixed">
		<origin rpy="0 0 0" xyz="0 -0.0220203446692936 0.03242" />
		<parent link="right_inner_finger" />
		<child link="right_inner_finger_pad" />
		<axis xyz="0 0 1" />
	</joint>
</robot>